2022-01-25 00:53:17 ERROR Traceback (most recent call last):
  File "/home/pedro.vaz/miniconda3/lib/python3.7/site-packages/wandb/apis/normalize.py", line 24, in wrapper
    return func(*args, **kwargs)
  File "/home/pedro.vaz/miniconda3/lib/python3.7/site-packages/wandb/apis/public.py", line 761, in artifact
    artifact = Artifact(self.client, entity, project, artifact_name)
  File "/home/pedro.vaz/miniconda3/lib/python3.7/site-packages/wandb/apis/public.py", line 3443, in __init__
    self._load()
  File "/home/pedro.vaz/miniconda3/lib/python3.7/site-packages/wandb/apis/public.py", line 3963, in _load
    % (self.entity, self.project, self._artifact_name)
ValueError: Project pedrovaz/exercise_5 does not contain artifact: "preprocessed_data.csv:latest"

During handling of the above exception, another exception occurred:

Traceback (most recent call last):
  File "/home/pedro.vaz/miniconda3/lib/python3.7/site-packages/wandb/cli/cli.py", line 86, in wrapper
    return func(*args, **kwargs)
  File "/home/pedro.vaz/miniconda3/lib/python3.7/site-packages/wandb/cli/cli.py", line 1585, in get
    artifact = public_api.artifact(full_path, type=type)
  File "/home/pedro.vaz/miniconda3/lib/python3.7/site-packages/wandb/apis/normalize.py", line 62, in wrapper
    six.reraise(CommError, CommError(message, err), sys.exc_info()[2])
  File "/home/pedro.vaz/miniconda3/lib/python3.7/site-packages/six.py", line 718, in reraise
    raise value.with_traceback(tb)
  File "/home/pedro.vaz/miniconda3/lib/python3.7/site-packages/wandb/apis/normalize.py", line 24, in wrapper
    return func(*args, **kwargs)
  File "/home/pedro.vaz/miniconda3/lib/python3.7/site-packages/wandb/apis/public.py", line 761, in artifact
    artifact = Artifact(self.client, entity, project, artifact_name)
  File "/home/pedro.vaz/miniconda3/lib/python3.7/site-packages/wandb/apis/public.py", line 3443, in __init__
    self._load()
  File "/home/pedro.vaz/miniconda3/lib/python3.7/site-packages/wandb/apis/public.py", line 3963, in _load
    % (self.entity, self.project, self._artifact_name)
wandb.errors.CommError: Project pedrovaz/exercise_5 does not contain artifact: "preprocessed_data.csv:latest"

2022-01-25 00:56:19 ERROR Traceback (most recent call last):
  File "/home/pedro.vaz/miniconda3/lib/python3.7/site-packages/wandb/apis/normalize.py", line 24, in wrapper
    return func(*args, **kwargs)
  File "/home/pedro.vaz/miniconda3/lib/python3.7/site-packages/wandb/apis/public.py", line 761, in artifact
    artifact = Artifact(self.client, entity, project, artifact_name)
  File "/home/pedro.vaz/miniconda3/lib/python3.7/site-packages/wandb/apis/public.py", line 3443, in __init__
    self._load()
  File "/home/pedro.vaz/miniconda3/lib/python3.7/site-packages/wandb/apis/public.py", line 3963, in _load
    % (self.entity, self.project, self._artifact_name)
ValueError: Project pedrovaz/exercise_5 does not contain artifact: "preprocessed_data.csv:latest"

During handling of the above exception, another exception occurred:

Traceback (most recent call last):
  File "/home/pedro.vaz/miniconda3/lib/python3.7/site-packages/wandb/cli/cli.py", line 86, in wrapper
    return func(*args, **kwargs)
  File "/home/pedro.vaz/miniconda3/lib/python3.7/site-packages/wandb/cli/cli.py", line 1585, in get
    artifact = public_api.artifact(full_path, type=type)
  File "/home/pedro.vaz/miniconda3/lib/python3.7/site-packages/wandb/apis/normalize.py", line 62, in wrapper
    six.reraise(CommError, CommError(message, err), sys.exc_info()[2])
  File "/home/pedro.vaz/miniconda3/lib/python3.7/site-packages/six.py", line 718, in reraise
    raise value.with_traceback(tb)
  File "/home/pedro.vaz/miniconda3/lib/python3.7/site-packages/wandb/apis/normalize.py", line 24, in wrapper
    return func(*args, **kwargs)
  File "/home/pedro.vaz/miniconda3/lib/python3.7/site-packages/wandb/apis/public.py", line 761, in artifact
    artifact = Artifact(self.client, entity, project, artifact_name)
  File "/home/pedro.vaz/miniconda3/lib/python3.7/site-packages/wandb/apis/public.py", line 3443, in __init__
    self._load()
  File "/home/pedro.vaz/miniconda3/lib/python3.7/site-packages/wandb/apis/public.py", line 3963, in _load
    % (self.entity, self.project, self._artifact_name)
wandb.errors.CommError: Project pedrovaz/exercise_5 does not contain artifact: "preprocessed_data.csv:latest"

